[2023-11-17 12:36:25,969] [INFO] [satosa.proxy_server.make_app] Running SATOSA version 8.4.0
[2023-11-17 12:36:25,969] [INFO] [satosa.base.__init__] Loading backend modules...
[2023-11-17 12:36:26,436] [DEBUG] [idpyoidc.client.oauth2.stand_alone_client.do_provider_info] ******************** do_provider_info ********************
[2023-11-17 12:36:26,436] [DEBUG] [idpyoidc.client.oauth2.do_request] do_request info: {'url': 'https://127.0.0.1:5000/.well-known/openid-configuration', 'method': 'GET'}
[2023-11-17 12:36:26,436] [DEBUG] [idpyoidc.client.oauth2.service_request] Doing request with: URL:https://127.0.0.1:5000/.well-known/openid-configuration, method:GET, data:None, https_args:{}
[2023-11-17 12:36:26,438] [DEBUG] [urllib3.connectionpool._new_conn] Starting new HTTPS connection (1): 127.0.0.1:5000
[2023-11-17 12:36:26,438] [ERROR] [idpyoidc.client.oauth2.get_response] Exception on request: HTTPSConnectionPool(host='127.0.0.1', port=5000): Max retries exceeded with url: /.well-known/openid-configuration (Caused by NewConnectionError('<urllib3.connection.HTTPSConnection object at 0x7faef4b9d3d0>: Failed to establish a new connection: [Errno 111] Connection refused'))
[2023-11-17 12:36:26,438] [ERROR] [satosa.proxy_server.make_app] Failed to create WSGI app.
Traceback (most recent call last):
  File "/usr/local/lib/python3.11/site-packages/idpyoidc/client/oauth2/__init__.py", line 214, in service_request
    response = service.get_response_ext(
               ^^^^^^^^^^^^^^^^^^^^^^^^
AttributeError: 'ProviderInfoDiscovery' object has no attribute 'get_response_ext'

During handling of the above exception, another exception occurred:

Traceback (most recent call last):
  File "/home/client7/.local/lib/python3.11/site-packages/urllib3/connection.py", line 203, in _new_conn
    sock = connection.create_connection(
           ^^^^^^^^^^^^^^^^^^^^^^^^^^^^^
  File "/home/client7/.local/lib/python3.11/site-packages/urllib3/util/connection.py", line 85, in create_connection
    raise err
  File "/home/client7/.local/lib/python3.11/site-packages/urllib3/util/connection.py", line 73, in create_connection
    sock.connect(sa)
ConnectionRefusedError: [Errno 111] Connection refused

The above exception was the direct cause of the following exception:

Traceback (most recent call last):
  File "/home/client7/.local/lib/python3.11/site-packages/urllib3/connectionpool.py", line 791, in urlopen
    response = self._make_request(
               ^^^^^^^^^^^^^^^^^^^
  File "/home/client7/.local/lib/python3.11/site-packages/urllib3/connectionpool.py", line 492, in _make_request
    raise new_e
  File "/home/client7/.local/lib/python3.11/site-packages/urllib3/connectionpool.py", line 468, in _make_request
    self._validate_conn(conn)
  File "/home/client7/.local/lib/python3.11/site-packages/urllib3/connectionpool.py", line 1097, in _validate_conn
    conn.connect()
  File "/home/client7/.local/lib/python3.11/site-packages/urllib3/connection.py", line 611, in connect
    self.sock = sock = self._new_conn()
                       ^^^^^^^^^^^^^^^^
  File "/home/client7/.local/lib/python3.11/site-packages/urllib3/connection.py", line 218, in _new_conn
    raise NewConnectionError(
urllib3.exceptions.NewConnectionError: <urllib3.connection.HTTPSConnection object at 0x7faef4b9d3d0>: Failed to establish a new connection: [Errno 111] Connection refused

The above exception was the direct cause of the following exception:

Traceback (most recent call last):
  File "/home/client7/.local/lib/python3.11/site-packages/requests/adapters.py", line 486, in send
    resp = conn.urlopen(
           ^^^^^^^^^^^^^
  File "/home/client7/.local/lib/python3.11/site-packages/urllib3/connectionpool.py", line 845, in urlopen
    retries = retries.increment(
              ^^^^^^^^^^^^^^^^^^
  File "/home/client7/.local/lib/python3.11/site-packages/urllib3/util/retry.py", line 515, in increment
    raise MaxRetryError(_pool, url, reason) from reason  # type: ignore[arg-type]
    ^^^^^^^^^^^^^^^^^^^^^^^^^^^^^^^^^^^^^^^^^^^^^^^^^^^
urllib3.exceptions.MaxRetryError: HTTPSConnectionPool(host='127.0.0.1', port=5000): Max retries exceeded with url: /.well-known/openid-configuration (Caused by NewConnectionError('<urllib3.connection.HTTPSConnection object at 0x7faef4b9d3d0>: Failed to establish a new connection: [Errno 111] Connection refused'))

During handling of the above exception, another exception occurred:

Traceback (most recent call last):
  File "/home/client7/.local/lib/python3.11/site-packages/satosa/proxy_server.py", line 197, in make_app
    res1 = WsgiApplication(satosa_config)
           ^^^^^^^^^^^^^^^^^^^^^^^^^^^^^^
  File "/home/client7/.local/lib/python3.11/site-packages/satosa/proxy_server.py", line 119, in __init__
    super().__init__(config)
  File "/home/client7/.local/lib/python3.11/site-packages/satosa/base.py", line 56, in __init__
    backends = load_backends(self.config, self._auth_resp_callback_func,
               ^^^^^^^^^^^^^^^^^^^^^^^^^^^^^^^^^^^^^^^^^^^^^^^^^^^^^^^^^
  File "/home/client7/.local/lib/python3.11/site-packages/satosa/plugin_loader.py", line 44, in load_backends
    backend_modules = _load_plugins(
                      ^^^^^^^^^^^^^^
  File "/home/client7/.local/lib/python3.11/site-packages/satosa/plugin_loader.py", line 181, in _load_plugins
    instance = module_class(callback, internal_attributes, module_config, base_url,
               ^^^^^^^^^^^^^^^^^^^^^^^^^^^^^^^^^^^^^^^^^^^^^^^^^^^^^^^^^^^^^^^^^^^^
  File "/home/client7/.local/lib/python3.11/site-packages/satosa/backends/idpy_oidc.py", line 52, in __init__
    self.client.do_provider_info()
  File "/usr/local/lib/python3.11/site-packages/idpyoidc/client/oauth2/stand_alone_client.py", line 70, in do_provider_info
    dynamic_provider_info_discovery(self, behaviour_args=behaviour_args)
  File "/usr/local/lib/python3.11/site-packages/idpyoidc/client/oauth2/__init__.py", line 333, in dynamic_provider_info_discovery
    response = client.do_request(service, behaviour_args=behaviour_args)
               ^^^^^^^^^^^^^^^^^^^^^^^^^^^^^^^^^^^^^^^^^^^^^^^^^^^^^^^^^
  File "/usr/local/lib/python3.11/site-packages/idpyoidc/client/oauth2/__init__.py", line 133, in do_request
    return self.service_request(
           ^^^^^^^^^^^^^^^^^^^^^
  File "/usr/local/lib/python3.11/site-packages/idpyoidc/client/oauth2/__init__.py", line 218, in service_request
    response = self.get_response(
               ^^^^^^^^^^^^^^^^^^
  File "/usr/local/lib/python3.11/site-packages/idpyoidc/client/oauth2/__init__.py", line 161, in get_response
    resp = self.httpc(method, url, data=body, headers=headers, **self.httpc_params)
           ^^^^^^^^^^^^^^^^^^^^^^^^^^^^^^^^^^^^^^^^^^^^^^^^^^^^^^^^^^^^^^^^^^^^^^^^
  File "/home/client7/.local/lib/python3.11/site-packages/requests/api.py", line 59, in request
    return session.request(method=method, url=url, **kwargs)
           ^^^^^^^^^^^^^^^^^^^^^^^^^^^^^^^^^^^^^^^^^^^^^^^^^
  File "/home/client7/.local/lib/python3.11/site-packages/requests/sessions.py", line 589, in request
    resp = self.send(prep, **send_kwargs)
           ^^^^^^^^^^^^^^^^^^^^^^^^^^^^^^
  File "/home/client7/.local/lib/python3.11/site-packages/requests/sessions.py", line 703, in send
    r = adapter.send(request, **kwargs)
        ^^^^^^^^^^^^^^^^^^^^^^^^^^^^^^^
  File "/home/client7/.local/lib/python3.11/site-packages/requests/adapters.py", line 519, in send
    raise ConnectionError(e, request=request)
requests.exceptions.ConnectionError: HTTPSConnectionPool(host='127.0.0.1', port=5000): Max retries exceeded with url: /.well-known/openid-configuration (Caused by NewConnectionError('<urllib3.connection.HTTPSConnection object at 0x7faef4b9d3d0>: Failed to establish a new connection: [Errno 111] Connection refused'))
